{
   "CVE_data_meta" : {
      "ASSIGNER" : "sfowler@redhat.com",
      "ID" : "CVE-2018-1061",
      "STATE" : "PUBLIC"
   },
   "affects" : {
      "vendor" : {
         "vendor_data" : [
            {
               "product" : {
                  "product_data" : [
                     {
                        "product_name" : "python",
                        "version" : {
                           "version_data" : [
                              {
                                 "version_value" : "python 2.7.15"
                              },
                              {
                                 "version_value" : "python 3.4.9"
                              },
                              {
                                 "version_value" : "python 3.5.6"
                              },
                              {
                                 "version_value" : "python 3.7.0"
                              }
                           ]
                        }
                     }
                  ]
               },
               "vendor_name" : "[UNKNOWN]"
            }
         ]
      }
   },
   "data_format" : "MITRE",
   "data_type" : "CVE",
   "data_version" : "4.0",
   "description" : {
      "description_data" : [
         {
            "lang" : "eng",
            "value" : "python before versions 2.7.15, 3.4.9, 3.5.6 and 3.7.0 is vulnerable to catastrophic backtracking in the difflib.IS_LINE_JUNK method. An attacker could use this flaw to cause denial of service."
         }
      ]
   },
   "impact" : {
      "cvss" : [
         [
            {
               "vectorString" : "6.5/CVSS:3.0/AV:N/AC:L/PR:N/UI:R/S:U/C:N/I:N/A:H",
               "version" : "3.0"
            }
         ]
      ]
   },
   "problemtype" : {
      "problemtype_data" : [
         {
            "description" : [
               {
                  "lang" : "eng",
                  "value" : "CWE-20"
               }
            ]
         }
      ]
   },
   "references" : {
      "reference_data" : [
         {
            "name" : "https://bugs.python.org/issue32981",
            "refsource" : "CONFIRM",
            "url" : "https://bugs.python.org/issue32981"
         },
         {
            "name" : "https://bugzilla.redhat.com/show_bug.cgi?id=CVE-2018-1061",
            "refsource" : "CONFIRM",
            "url" : "https://bugzilla.redhat.com/show_bug.cgi?id=CVE-2018-1061"
         },
         {
            "name" : "https://docs.python.org/3.6/whatsnew/changelog.html#python-3-6-5-final",
            "refsource" : "CONFIRM",
            "url" : "https://docs.python.org/3.6/whatsnew/changelog.html#python-3-6-5-final"
         }
      ]
   }
}
